2025-03-21 18:28:55,556 - WARNING - PyNaCl is not installed, voice will NOT be supported
2025-03-21 18:28:55,628 - INFO - logging in using static token
2025-03-21 18:28:56,293 - INFO - Shard ID None has connected to Gateway (Session ID: ad6925cd846179e09643ac080f1c639a).
2025-03-21 18:28:58,305 - INFO - Bot is ready! Logged in as Battle Buddy
2025-03-21 18:28:58,633 - INFO - Synced 6 command(s)
2025-03-21 18:30:59,952 - ERROR - Ignoring exception in command 'who'
Traceback (most recent call last):
  File "C:\Users\lksno\AppData\Local\Packages\PythonSoftwareFoundation.Python.3.12_qbz5n2kfra8p0\LocalCache\local-packages\Python312\site-packages\discord\app_commands\commands.py", line 858, in _do_call
    return await self._callback(interaction, **params)  # type: ignore
           ^^^^^^^^^^^^^^^^^^^^^^^^^^^^^^^^^^^^^^^^^^^
  File "C:\Users\lksno\Dropbox\PC\Desktop\battlebuddy-main\battlebuddy.py", line 178, in who
    character = random.choice(characters)
                ^^^^^^^^^^^^^
AttributeError: 'Command' object has no attribute 'choice'

The above exception was the direct cause of the following exception:

Traceback (most recent call last):
  File "C:\Users\lksno\AppData\Local\Packages\PythonSoftwareFoundation.Python.3.12_qbz5n2kfra8p0\LocalCache\local-packages\Python312\site-packages\discord\app_commands\tree.py", line 1310, in _call
    await command._invoke_with_namespace(interaction, namespace)
  File "C:\Users\lksno\AppData\Local\Packages\PythonSoftwareFoundation.Python.3.12_qbz5n2kfra8p0\LocalCache\local-packages\Python312\site-packages\discord\app_commands\commands.py", line 883, in _invoke_with_namespace
    return await self._do_call(interaction, transformed_values)
           ^^^^^^^^^^^^^^^^^^^^^^^^^^^^^^^^^^^^^^^^^^^^^^^^^^^^
  File "C:\Users\lksno\AppData\Local\Packages\PythonSoftwareFoundation.Python.3.12_qbz5n2kfra8p0\LocalCache\local-packages\Python312\site-packages\discord\app_commands\commands.py", line 876, in _do_call
    raise CommandInvokeError(self, e) from e
discord.app_commands.errors.CommandInvokeError: Command 'who' raised an exception: AttributeError: 'Command' object has no attribute 'choice'
2025-03-21 18:31:19,568 - ERROR - Ignoring exception in command 'who'
Traceback (most recent call last):
  File "C:\Users\lksno\AppData\Local\Packages\PythonSoftwareFoundation.Python.3.12_qbz5n2kfra8p0\LocalCache\local-packages\Python312\site-packages\discord\app_commands\commands.py", line 858, in _do_call
    return await self._callback(interaction, **params)  # type: ignore
           ^^^^^^^^^^^^^^^^^^^^^^^^^^^^^^^^^^^^^^^^^^^
  File "C:\Users\lksno\Dropbox\PC\Desktop\battlebuddy-main\battlebuddy.py", line 178, in who
    character = random.choice(characters)
                ^^^^^^^^^^^^^
AttributeError: 'Command' object has no attribute 'choice'

The above exception was the direct cause of the following exception:

Traceback (most recent call last):
  File "C:\Users\lksno\AppData\Local\Packages\PythonSoftwareFoundation.Python.3.12_qbz5n2kfra8p0\LocalCache\local-packages\Python312\site-packages\discord\app_commands\tree.py", line 1310, in _call
    await command._invoke_with_namespace(interaction, namespace)
  File "C:\Users\lksno\AppData\Local\Packages\PythonSoftwareFoundation.Python.3.12_qbz5n2kfra8p0\LocalCache\local-packages\Python312\site-packages\discord\app_commands\commands.py", line 883, in _invoke_with_namespace
    return await self._do_call(interaction, transformed_values)
           ^^^^^^^^^^^^^^^^^^^^^^^^^^^^^^^^^^^^^^^^^^^^^^^^^^^^
  File "C:\Users\lksno\AppData\Local\Packages\PythonSoftwareFoundation.Python.3.12_qbz5n2kfra8p0\LocalCache\local-packages\Python312\site-packages\discord\app_commands\commands.py", line 876, in _do_call
    raise CommandInvokeError(self, e) from e
discord.app_commands.errors.CommandInvokeError: Command 'who' raised an exception: AttributeError: 'Command' object has no attribute 'choice'
2025-03-21 18:31:44,675 - ERROR - Ignoring exception in command 'who'
Traceback (most recent call last):
  File "C:\Users\lksno\AppData\Local\Packages\PythonSoftwareFoundation.Python.3.12_qbz5n2kfra8p0\LocalCache\local-packages\Python312\site-packages\discord\app_commands\commands.py", line 858, in _do_call
    return await self._callback(interaction, **params)  # type: ignore
           ^^^^^^^^^^^^^^^^^^^^^^^^^^^^^^^^^^^^^^^^^^^
  File "C:\Users\lksno\Dropbox\PC\Desktop\battlebuddy-main\battlebuddy.py", line 178, in who
    character = random.choice(characters)
                ^^^^^^^^^^^^^
AttributeError: 'Command' object has no attribute 'choice'

The above exception was the direct cause of the following exception:

Traceback (most recent call last):
  File "C:\Users\lksno\AppData\Local\Packages\PythonSoftwareFoundation.Python.3.12_qbz5n2kfra8p0\LocalCache\local-packages\Python312\site-packages\discord\app_commands\tree.py", line 1310, in _call
    await command._invoke_with_namespace(interaction, namespace)
  File "C:\Users\lksno\AppData\Local\Packages\PythonSoftwareFoundation.Python.3.12_qbz5n2kfra8p0\LocalCache\local-packages\Python312\site-packages\discord\app_commands\commands.py", line 883, in _invoke_with_namespace
    return await self._do_call(interaction, transformed_values)
           ^^^^^^^^^^^^^^^^^^^^^^^^^^^^^^^^^^^^^^^^^^^^^^^^^^^^
  File "C:\Users\lksno\AppData\Local\Packages\PythonSoftwareFoundation.Python.3.12_qbz5n2kfra8p0\LocalCache\local-packages\Python312\site-packages\discord\app_commands\commands.py", line 876, in _do_call
    raise CommandInvokeError(self, e) from e
discord.app_commands.errors.CommandInvokeError: Command 'who' raised an exception: AttributeError: 'Command' object has no attribute 'choice'
2025-03-21 18:31:59,854 - ERROR - Ignoring exception in command 'random'
Traceback (most recent call last):
  File "C:\Users\lksno\AppData\Local\Packages\PythonSoftwareFoundation.Python.3.12_qbz5n2kfra8p0\LocalCache\local-packages\Python312\site-packages\discord\app_commands\commands.py", line 858, in _do_call
    return await self._callback(interaction, **params)  # type: ignore
           ^^^^^^^^^^^^^^^^^^^^^^^^^^^^^^^^^^^^^^^^^^^
  File "C:\Users\lksno\Dropbox\PC\Desktop\battlebuddy-main\battlebuddy.py", line 204, in random
    game = random.choice(list(CHARACTERS.keys()))
           ^^^^^^^^^^^^^
AttributeError: 'Command' object has no attribute 'choice'

The above exception was the direct cause of the following exception:

Traceback (most recent call last):
  File "C:\Users\lksno\AppData\Local\Packages\PythonSoftwareFoundation.Python.3.12_qbz5n2kfra8p0\LocalCache\local-packages\Python312\site-packages\discord\app_commands\tree.py", line 1310, in _call
    await command._invoke_with_namespace(interaction, namespace)
  File "C:\Users\lksno\AppData\Local\Packages\PythonSoftwareFoundation.Python.3.12_qbz5n2kfra8p0\LocalCache\local-packages\Python312\site-packages\discord\app_commands\commands.py", line 883, in _invoke_with_namespace
    return await self._do_call(interaction, transformed_values)
           ^^^^^^^^^^^^^^^^^^^^^^^^^^^^^^^^^^^^^^^^^^^^^^^^^^^^
  File "C:\Users\lksno\AppData\Local\Packages\PythonSoftwareFoundation.Python.3.12_qbz5n2kfra8p0\LocalCache\local-packages\Python312\site-packages\discord\app_commands\commands.py", line 876, in _do_call
    raise CommandInvokeError(self, e) from e
discord.app_commands.errors.CommandInvokeError: Command 'random' raised an exception: AttributeError: 'Command' object has no attribute 'choice'
2025-03-21 18:39:10,338 - WARNING - PyNaCl is not installed, voice will NOT be supported
2025-03-21 18:39:10,341 - INFO - logging in using static token
2025-03-21 18:39:10,998 - INFO - Shard ID None has connected to Gateway (Session ID: dbe1c06d3669ad65e9797579e68e4b5f).
2025-03-21 18:39:13,041 - INFO - Bot is ready! Logged in as Battle Buddy
2025-03-21 18:39:13,263 - INFO - Synced 6 command(s)
2025-03-21 18:39:23,192 - ERROR - Application command error: Command 'who' raised an exception: AttributeError: 'Command' object has no attribute 'choice'
2025-03-21 18:39:32,511 - ERROR - Application command error: Command 'who' raised an exception: AttributeError: 'Command' object has no attribute 'choice'
2025-03-21 18:40:12,400 - ERROR - Application command error: Command 'who' raised an exception: AttributeError: 'Command' object has no attribute 'choice'
2025-03-21 18:41:23,565 - WARNING - PyNaCl is not installed, voice will NOT be supported
2025-03-21 18:41:23,568 - INFO - logging in using static token
2025-03-21 18:41:24,284 - INFO - Shard ID None has connected to Gateway (Session ID: 0f1d47ccfe89eefe2ea2d9893af1d5b0).
2025-03-21 18:41:26,291 - INFO - Bot is ready! Logged in as Battle Buddy
2025-03-21 18:41:26,468 - INFO - Synced 6 command(s)
2025-03-21 18:41:42,375 - ERROR - Error in random command: 'Command' object has no attribute 'choice'
2025-03-21 18:41:49,934 - ERROR - Error in who command: 'Command' object has no attribute 'choice'
2025-03-21 18:42:02,611 - ERROR - Error in who command: 'Command' object has no attribute 'choice'
2025-03-21 18:43:35,946 - WARNING - PyNaCl is not installed, voice will NOT be supported
2025-03-21 18:43:35,950 - INFO - logging in using static token
2025-03-21 18:43:36,590 - INFO - Shard ID None has connected to Gateway (Session ID: c3a3645a03c8d7b6f975635b8fdab9f2).
2025-03-21 18:43:38,614 - INFO - Bot is ready! Logged in as Battle Buddy
2025-03-21 18:43:38,876 - INFO - Synced 6 command(s)
2025-03-21 18:50:24,244 - WARNING - PyNaCl is not installed, voice will NOT be supported
2025-03-21 18:50:24,248 - INFO - logging in using static token
2025-03-21 18:50:24,935 - INFO - Shard ID None has connected to Gateway (Session ID: bd9275e85879baef2791b981ea2f5508).
2025-03-21 18:50:26,936 - INFO - Bot is ready! Logged in as Battle Buddy
2025-03-21 18:50:27,169 - INFO - Synced 6 command(s)
2025-03-21 18:56:44,394 - WARNING - PyNaCl is not installed, voice will NOT be supported
2025-03-21 18:56:44,396 - INFO - logging in using static token
2025-03-21 18:56:45,482 - INFO - Shard ID None has connected to Gateway (Session ID: 0d138980973eacc823227b156aa7ccfd).
2025-03-21 18:56:47,495 - INFO - Bot is ready! Logged in as Battle Buddy
2025-03-21 18:56:47,705 - INFO - Synced 6 command(s)
2025-03-21 21:38:37,325 - INFO - Shard ID None has successfully RESUMED session 0d138980973eacc823227b156aa7ccfd.
2025-03-21 22:51:05,894 - INFO - Shard ID None has successfully RESUMED session 0d138980973eacc823227b156aa7ccfd.
